Workbook

Sheet Applications
A1: Cristian Arcidiacono — 2026–27 job market
A2: This version: 19 October 2026.
A4: Institution | B4: Position | C4: Location | D4: Track · letter set | E4: Application deadline | F4: Letters due | G4: Days until letters due | H4: Letters required | I4: How letters are submitted | J4: Portal / address / timing | K4: Referee 1 | L4: Referee 2 | M4: Referee 3 | N4: Referee 4 | O4: All referees | P4: Letter status - for Cristian
A5: St John's College, Oxford | B5: Career Development Research Fellowship in Economics (4 yrs from Oct 2027) | C5: Oxford, UK | D5: Fellowship · Macro / economics | E5: 46318 | F5: 46325 | G5: =IF(F5<>"",F5-TODAY(),IF(E5<>"",E5-TODAY(),"")) -> 11 | H5: Names only at submission; 2 reports requested by the college | I5: College requests reports directly | J5: Reports due 12:00 noon UK, Fri 30 Oct; application 1pm Fri 23 Oct | K5: Benigno | L5: Reis | O5: =_xlfn.TEXTJOIN(", ",TRUE(),K5:N5) -> Benigno, Reis | P5: Names only
A6: University of St. Gallen | B6: Assistant Professor (tenure track), Macroeconomics | C6: St. Gallen, CH | D6: Academic · Macro / economics | E6: 46326 | F6: 46326 | G6: =IF(F6<>"",F6-TODAY(),IF(E6<>"",E6-TODAY(),"")) -> 12 | H6: 2 | I6: University portal (facultyrecruiting.unisg.ch) | J6: Contact facultyposition@unisg.ch (Prof. Winfried Koeniger) | K6: Benigno | L6: Reis | O6: =_xlfn.TEXTJOIN(", ",TRUE(),K6:N6) -> Benigno, Reis | P6: Referee action needed
A7: OECD, Economics Department | B7: Junior Economists / Economists (2-yr, Paris) | C7: Paris, FR | D7: Policy | E7: 46327 | F7: 46327 | G7: =IF(F7<>"",F7-TODAY(),IF(E7<>"",E7-TODAY(),"")) -> 13 | H7: 3 | I7: EconJobMarket (ad 12569) + email | J7: econjobmarket.org/positions/12569; JMP/CV/cover letter to mathieu.miranda@oecd.org | K7: Benigno | L7: Reis | M7: Hofmann | O7: =_xlfn.TEXTJOIN(", ",TRUE(),K7:N7) -> Benigno, Reis, Hofmann | P7: On platform – check attached
A8: Northwestern Kellogg | B8: Assistant Professor of Finance | C8: Evanston, US | D8: Academic · Finance | E8: 46327 | F8: 46327 | G8: =IF(F8<>"",F8-TODAY(),IF(E8<>"",E8-TODAY(),"")) -> 13 | H8: 3 | I8: Kellogg faculty-recruiting portal | J8: facultyrecruiting.northwestern.edu/apply/MjYzMg | K8: Benigno | L8: Reis | M8: Chaudhary | O8: =_xlfn.TEXTJOIN(", ",TRUE(),K8:N8) -> Benigno, Reis, Chaudhary | P8: Referee action needed
A9: Texas A&M University | B9: Assistant Professor of International Macroeconomics | C9: College Station, US | D9: Academic · Macro / economics | E9: 46327 | F9: 46327 | G9: =IF(F9<>"",F9-TODAY(),IF(E9<>"",E9-TODAY(),"")) -> 13 | H9: Not stated – check ad | I9: AEA JOE | J9: JOE listing (Aug 2026) | K9: Benigno | L9: Reis | M9: Hofmann | O9: =_xlfn.TEXTJOIN(", ",TRUE(),K9:N9) -> Benigno, Reis, Hofmann | P9: On platform – check attached
A10: EPFL / Swiss Finance Institute | B10: Faculty positions in Finance (two posts, one ad) | C10: Lausanne, CH | D10: Academic · Finance | E10: 46327 | G10: =IF(F10<>"",F10-TODAY(),IF(E10<>"",E10-TODAY(),"")) -> 13 | H10: Names only (3–5) | I10: Names supplied; EPFL requests letters later | J10: epfl.ch/about/working/?p=9052 | K10: Benigno | L10: Reis | M10: Chaudhary | O10: =_xlfn.TEXTJOIN(", ",TRUE(),K10:N10) -> Benigno, Reis, Chaudhary | P10: Names only
A11: Universitat Autònoma de Barcelona (UFAE / BSE) | B11: Assistant and Associate Professor positions (any field) | C11: Bellaterra, ES | D11: Academic · Macro / economics | E11: 46327 | F11: 46327 | G11: =IF(F11<>"",F11-TODAY(),IF(E11<>"",E11-TODAY(),"")) -> 13 | H11: 3 | I11: EconJobMarket (ad 12666) | J11: Online interviews 9–11 Dec | K11: Benigno | L11: Reis | M11: Hofmann | O11: =_xlfn.TEXTJOIN(", ",TRUE(),K11:N11) -> Benigno, Reis, Hofmann | P11: On platform – check attached
A12: Imperial College Business School | B12: Assistant/Associate/Full Professor in Economics | C12: London, UK | D12: Academic · Macro / economics | E12: 46329 | F12: 46329 | G12: =IF(F12<>"",F12-TODAY(),IF(E12<>"",E12-TODAY(),"")) -> 15 | H12: 3 | I12: EconJobMarket (ad 12773) | J12: econjobmarket.org/positions/12773 | K12: Benigno | L12: Reis | M12: Hofmann | O12: =_xlfn.TEXTJOIN(", ",TRUE(),K12:N12) -> Benigno, Reis, Hofmann | P12: On platform – check attached
A13: Oxford Saïd Business School | B13: Tenure-track position in Financial Economics | C13: Oxford, UK | D13: Academic · Finance | E13: 46332 | G13: =IF(F13<>"",F13-TODAY(),IF(E13<>"",E13-TODAY(),"")) -> 18 | H13: None at this stage | I13: Expression-of-interest stage only | J13: careers.sbs.ox.ac.uk vacancy 1024 | K13: Benigno | L13: Reis | M13: Chaudhary | O13: =_xlfn.TEXTJOIN(", ",TRUE(),K13:N13) -> Benigno, Reis, Chaudhary | P13: Not needed yet
A14: MIT, Department of Economics | B14: Assistant Professor (any field) | C14: Cambridge MA, US | D14: Academic · Macro / economics | E14: 46332 | F14: 46332 | G14: =IF(F14<>"",F14-TODAY(),IF(E14<>"",E14-TODAY(),"")) -> 18 | H14: 3 | I14: MIT portal / EconJobMarket (ad 12621) | J14: Letters also due 6 Nov | K14: Benigno | L14: Reis | M14: Hofmann | O14: =_xlfn.TEXTJOIN(", ",TRUE(),K14:N14) -> Benigno, Reis, Hofmann | P14: On platform – check attached
A15: Stanford University, Department of Economics | B15: Assistant Professor (any field) | C15: Stanford, US | D15: Academic · Macro / economics | E15: 46332 | F15: 46332 | G15: =IF(F15<>"",F15-TODAY(),IF(E15<>"",E15-TODAY(),"")) -> 18 | H15: 3 | I15: EconJobMarket (ad 12662) | K15: Benigno | L15: Reis | M15: Hofmann | O15: =_xlfn.TEXTJOIN(", ",TRUE(),K15:N15) -> Benigno, Reis, Hofmann | P15: On platform – check attached
A16: Cornell University, Economics | B16: Assistant Professor (international) | C16: Ithaca, US | D16: Academic · Macro / economics | E16: 46333 | F16: 46333 | G16: =IF(F16<>"",F16-TODAY(),IF(E16<>"",E16-TODAY(),"")) -> 19 | H16: Not stated – check ad | I16: See JOE ad | K16: Benigno | L16: Reis | M16: Hofmann | O16: =_xlfn.TEXTJOIN(", ",TRUE(),K16:N16) -> Benigno, Reis, Hofmann | P16: On platform – check attached
A17: Yale University, Department of Economics | B17: Assistant Professor (any field) | C17: New Haven, US | D17: Academic · Macro / economics | E17: 46333 | F17: 46333 | G17: =IF(F17<>"",F17-TODAY(),IF(E17<>"",E17-TODAY(),"")) -> 19 | H17: 3 | I17: Interfolio 192292 | J17: JOE shows 31 Jan 2027, but the ad asks for applications before 7 Nov | K17: Benigno | L17: Reis | M17: Hofmann | O17: =_xlfn.TEXTJOIN(", ",TRUE(),K17:N17) -> Benigno, Reis, Hofmann | P17: On platform – check attached
A18: University of Michigan | B18: Assistant Professor (any field) | C18: Ann Arbor, US | D18: Academic · Macro / economics | E18: 46333 | F18: 46333 | G18: =IF(F18<>"",F18-TODAY(),IF(E18<>"",E18-TODAY(),"")) -> 19 | H18: 3 | I18: EconJobMarket (ad 12669) | J18: First consideration 7 Nov; final 31 Dec | K18: Benigno | L18: Reis | M18: Hofmann | O18: =_xlfn.TEXTJOIN(", ",TRUE(),K18:N18) -> Benigno, Reis, Hofmann | P18: On platform – check attached
A19: Federal Reserve Bank of New York | B19: Economist (PhD), Research & Statistics | C19: New York, US | D19: Policy | E19: 46327 | F19: 46334 | G19: =IF(F19<>"",F19-TODAY(),IF(E19<>"",E19-TODAY(),"")) -> 20 | H19: 3 | I19: NY Fed Workday portal | J19: Letters accepted up to one week after the application deadline | K19: Benigno | L19: Reis | M19: Hofmann | O19: =_xlfn.TEXTJOIN(", ",TRUE(),K19:N19) -> Benigno, Reis, Hofmann | P19: Referee action needed
A20: Bank for International Settlements (MED) | B20: Economist / Senior Economist / Principal Economist | C20: Basel, CH | D20: Policy | E20: 46334 | F20: 46334 | G20: =IF(F20<>"",F20-TODAY(),IF(E20<>"",E20-TODAY(),"")) -> 20 | H20: 3 | I20: AEA JOE only | J20: JOE listing 2026-02_111478115 – letters uploaded through JOE | K20: Benigno | L20: Reis | M20: Hofmann | O20: =_xlfn.TEXTJOIN(", ",TRUE(),K20:N20) -> Benigno, Reis, Hofmann | P20: On platform – check attached
A21: Toulouse School of Economics | B21: Assistant Professor (tenure track) | C21: Toulouse, FR | D21: Academic · Macro / economics | E21: 46334 | F21: 46334 | G21: =IF(F21<>"",F21-TODAY(),IF(E21<>"",E21-TODAY(),"")) -> 20 | H21: 3 | I21: EconJobMarket (ad 12736) | J21: econjobmarket.org/positions/12736 | K21: Benigno | L21: Reis | M21: Hofmann | O21: =_xlfn.TEXTJOIN(", ",TRUE(),K21:N21) -> Benigno, Reis, Hofmann | P21: On platform – check attached
A22: University of Konstanz | B22: Assistant Professor / Postdoc (economics) | C22: Konstanz, DE | D22: Academic · Macro / economics | E22: 46334 | F22: 46334 | G22: =IF(F22<>"",F22-TODAY(),IF(E22<>"",E22-TODAY(),"")) -> 20 | H22: 2 | I22: See ad | K22: Benigno | L22: Reis | O22: =_xlfn.TEXTJOIN(", ",TRUE(),K22:N22) -> Benigno, Reis | P22: Referee action needed
A23: Clare / Churchill / Fitzwilliam / Murray Edwards / Trinity Hall (Cambridge) | B23: Early Career Research Fellowships 2027 (joint scheme, 3 yrs) | C23: Cambridge, UK | D23: Fellowship · Macro / economics | E23: 46335 | F23: 46335 | G23: =IF(F23<>"",F23-TODAY(),IF(E23<>"",E23-TODAY(),"")) -> 21 | H23: Per further particulars (jrf.chu.cam.ac.uk/rf_2027) | I23: College online form | J23: clare.cam.ac.uk/JRF-Eligibility | K23: Benigno | L23: Reis | O23: =_xlfn.TEXTJOIN(", ",TRUE(),K23:N23) -> Benigno, Reis | P23: Referee action needed
A24: Harvard Business School – BGIE | B24: Assistant Professor, Business, Government & the International Economy | C24: Boston, US | D24: Academic · Macro / economics | E24: 46335 | F24: 46335 | G24: =IF(F24<>"",F24-TODAY(),IF(E24<>"",E24-TODAY(),"")) -> 21 | H24: Not stated – check ad | I24: Interfolio 192151 | J24: apply.interfolio.com/192151 | K24: Benigno | L24: Reis | M24: Hofmann | O24: =_xlfn.TEXTJOIN(", ",TRUE(),K24:N24) -> Benigno, Reis, Hofmann | P24: On platform – check attached
A25: INSEAD, Finance Area | B25: Assistant Professor of Finance | C25: Fontainebleau, FR | D25: Academic · Finance | E25: 46336 | F25: 46336 | G25: =IF(F25<>"",F25-TODAY(),IF(E25<>"",E25-TODAY(),"")) -> 22 | H25: 3 or more – uploaded by the candidate | I25: Interfolio 194812 – candidate uploads confidential letters | J25: apply.interfolio.com/194812 | K25: Benigno | L25: Reis | M25: Chaudhary | O25: =_xlfn.TEXTJOIN(", ",TRUE(),K25:N25) -> Benigno, Reis, Chaudhary | P25: On platform – check attached
A26: Stanford GSB, Economics | B26: Faculty positions in Economics | C26: Stanford, US | D26: Academic · Macro / economics | E26: 46336 | F26: 46336 | G26: =IF(F26<>"",F26-TODAY(),IF(E26<>"",E26-TODAY(),"")) -> 22 | H26: 3 | I26: AcademicJobsOnline | K26: Benigno | L26: Reis | M26: Hofmann | O26: =_xlfn.TEXTJOIN(", ",TRUE(),K26:N26) -> Benigno, Reis, Hofmann | P26: On platform – check attached
A27: Banca d'Italia | B27: Research Fellowships for young economists 2026 (4 posts; 12+12 months, from Nov 2027) | C27: Rome, IT | D27: Policy | E27: 46339 | F27: 46339 | G27: =IF(F27<>"",F27-TODAY(),IF(E27<>"",E27-TODAY(),"")) -> 25 | H27: At least 2 – SIGNED, sent by the referee | I27: Referee emails the letter directly to the Bank | J27: personale.fellowship@bancaditalia.it – deadline 12:00 CET, 13 Nov | K27: Benigno | L27: Reis | M27: Hofmann | O27: =_xlfn.TEXTJOIN(", ",TRUE(),K27:N27) -> Benigno, Reis, Hofmann | P27: Referee action needed
A28: EIEF (Einaudi Institute) | B28: Assistant Professor (2 posts) | C28: Rome, IT | D28: Academic · Macro / economics | E28: 46339 | F28: 46339 | G28: =IF(F28<>"",F28-TODAY(),IF(E28<>"",E28-TODAY(),"")) -> 25 | H28: 3 | I28: EconJobMarket (ad 12688) | J28: econjobmarket.org/positions/12688 | K28: Benigno | L28: Reis | M28: Hofmann | O28: =_xlfn.TEXTJOIN(", ",TRUE(),K28:N28) -> Benigno, Reis, Hofmann | P28: On platform – check attached
A29: IIES, Stockholm University | B29: Tenure-track Assistant Professor | C29: Stockholm, SE | D29: Academic · Macro / economics | E29: 46339 | F29: 46339 | G29: =IF(F29<>"",F29-TODAY(),IF(E29<>"",E29-TODAY(),"")) -> 25 | H29: 3 | I29: EconJobMarket (ad 12840) | J29: econjobmarket.org/positions/12840 | K29: Benigno | L29: Reis | M29: Hofmann | O29: =_xlfn.TEXTJOIN(", ",TRUE(),K29:N29) -> Benigno, Reis, Hofmann | P29: On platform – check attached
A30: UCL, Department of Economics | B30: Assistant Professor (Lecturer) in Economics | C30: London, UK | D30: Academic · Macro / economics | E30: 46339 | F30: 46339 | G30: =IF(F30<>"",F30-TODAY(),IF(E30<>"",E30-TODAY(),"")) -> 25 | H30: 3 | I30: EconJobMarket (ad 12850) | J30: econjobmarket.org/positions/12850 | K30: Benigno | L30: Reis | M30: Hofmann | O30: =_xlfn.TEXTJOIN(", ",TRUE(),K30:N30) -> Benigno, Reis, Hofmann | P30: On platform – check attached
A31: UCL, Economics / School of Management | B31: Assistant Professor (Lecturer) in Finance | C31: London, UK | D31: Academic · Finance | E31: 46339 | F31: 46339 | G31: =IF(F31<>"",F31-TODAY(),IF(E31<>"",E31-TODAY(),"")) -> 25 | H31: 3 | I31: EconJobMarket (ad 12826) | J31: econjobmarket.org/positions/12826 | K31: Benigno | L31: Reis | M31: Chaudhary | O31: =_xlfn.TEXTJOIN(", ",TRUE(),K31:N31) -> Benigno, Reis, Chaudhary | P31: On platform – check attached
A32: HEC Paris | B32: Assistant Professor of Finance | C32: Jouy-en-Josas, FR | D32: Academic · Finance | E32: 46339 | F32: 46339 | G32: =IF(F32<>"",F32-TODAY(),IF(E32<>"",E32-TODAY(),"")) -> 25 | H32: 3 | I32: EconJobMarket (ad 12819) | J32: econjobmarket.org/positions/12819 | K32: Benigno | L32: Reis | M32: Chaudhary | O32: =_xlfn.TEXTJOIN(", ",TRUE(),K32:N32) -> Benigno, Reis, Chaudhary | P32: On platform – check attached
A33: Columbia University, Economics | B33: Assistant Professor (junior) | C33: New York, US | D33: Academic · Macro / economics | E33: 46339 | F33: 46339 | G33: =IF(F33<>"",F33-TODAY(),IF(E33<>"",E33-TODAY(),"")) -> 25 | H33: 3 | I33: EconJobMarket (ad 12750) | J33: econjobmarket.org/positions/12750 | K33: Benigno | L33: Reis | M33: Hofmann | O33: =_xlfn.TEXTJOIN(", ",TRUE(),K33:N33) -> Benigno, Reis, Hofmann | P33: On platform – check attached
A34: LSE, Department of Finance | B34: Assistant Professor of Finance | C34: London, UK | D34: Academic · Finance | E34: 46339 | F34: 46339 | G34: =IF(F34<>"",F34-TODAY(),IF(E34<>"",E34-TODAY(),"")) -> 25 | H34: Not stated – check ad | I34: AEA JOE / LSE portal | K34: Benigno | L34: Reis | M34: Chaudhary | O34: =_xlfn.TEXTJOIN(", ",TRUE(),K34:N34) -> Benigno, Reis, Chaudhary | P34: On platform – check attached
A35: McGill, Desautels | B35: Tenure-track position in Finance | C35: Montréal, CA | D35: Academic · Finance | E35: 46339 | F35: 46339 | G35: =IF(F35<>"",F35-TODAY(),IF(E35<>"",E35-TODAY(),"")) -> 25 | H35: 3 | I35: McGill Workday | J35: Date unverified | K35: Benigno | L35: Reis | M35: Chaudhary | O35: =_xlfn.TEXTJOIN(", ",TRUE(),K35:N35) -> Benigno, Reis, Chaudhary | P35: Referee action needed
A36: Yale School of Management | B36: Assistant or Associate Professor of Economics | C36: New Haven, US | D36: Academic · Macro / economics | E36: 46339 | F36: 46339 | G36: =IF(F36<>"",F36-TODAY(),IF(E36<>"",E36-TODAY(),"")) -> 25 | H36: Not stated – check ad | I36: Interfolio 195222 | J36: apply.interfolio.com/195222 | K36: Benigno | L36: Reis | M36: Hofmann | O36: =_xlfn.TEXTJOIN(", ",TRUE(),K36:N36) -> Benigno, Reis, Hofmann | P36: On platform – check attached
A37: Universidad Carlos III de Madrid | B37: Assistant Professor of Economics | C37: Getafe, ES | D37: Academic · Macro / economics | E37: 46339 | F37: 46339 | G37: =IF(F37<>"",F37-TODAY(),IF(E37<>"",E37-TODAY(),"")) -> 25 | H37: 3 | I37: EconJobMarket (ad 12677) | J37: Online interviews 14–17 Dec | K37: Benigno | L37: Reis | M37: Hofmann | O37: =_xlfn.TEXTJOIN(", ",TRUE(),K37:N37) -> Benigno, Reis, Hofmann | P37: On platform – check attached
A38: University College London – Stone Centre | B38: Research Fellow (wealth inequality, macro) | C38: London, UK | D38: Fellowship · Macro / economics | E38: 46339 | F38: 46339 | G38: =IF(F38<>"",F38-TODAY(),IF(E38<>"",E38-TODAY(),"")) -> 25 | H38: 3 | I38: EconJobMarket (ad 12781) | K38: Benigno | L38: Reis | M38: Hofmann | O38: =_xlfn.TEXTJOIN(", ",TRUE(),K38:N38) -> Benigno, Reis, Hofmann | P38: On platform – check attached
A39: Bocconi University, Department of Finance | B39: Assistant Professor of Finance (tenure track) | C39: Milan, IT | D39: Academic · Finance | E39: 46341 | F39: 46341 | G39: =IF(F39<>"",F39-TODAY(),IF(E39<>"",E39-TODAY(),"")) -> 27 | H39: 3 | I39: Bocconi job-market portal | J39: jobmarket.unibocconi.eu/?id=1005 – 23:59 Italian time | K39: Benigno | L39: Reis | M39: Chaudhary | O39: =_xlfn.TEXTJOIN(", ",TRUE(),K39:N39) -> Benigno, Reis, Chaudhary | P39: Referee action needed
A40: Université de Montréal | B40: Assistant Professor of Macroeconomics | C40: Montréal, CA | D40: Academic · Macro / economics | E40: 46341 | F40: 46341 | G40: =IF(F40<>"",F40-TODAY(),IF(E40<>"",E40-TODAY(),"")) -> 27 | H40: 3 | I40: EconJobMarket (ad 12645) | J40: econjobmarket.org/positions/12645 | K40: Benigno | L40: Reis | M40: Hofmann | O40: =_xlfn.TEXTJOIN(", ",TRUE(),K40:N40) -> Benigno, Reis, Hofmann | P40: On platform – check attached
A41: Erasmus School of Economics | B41: Assistant Professor in Macroeconomics / International Economics (TT) | C41: Rotterdam, NL | D41: Academic · Macro / economics | E41: 46341 | F41: 46341 | G41: =IF(F41<>"",F41-TODAY(),IF(E41<>"",E41-TODAY(),"")) -> 27 | H41: 3 | I41: EconJobMarket (ad 12857) | J41: econjobmarket.org/positions/12857 | K41: Benigno | L41: Reis | M41: Hofmann | O41: =_xlfn.TEXTJOIN(", ",TRUE(),K41:N41) -> Benigno, Reis, Hofmann | P41: On platform – check attached
...

Sheet By referee
A1: Letters per referee — live counts from the Applications sheet
A2: Counts update automatically when referee assignments or statuses change on the first sheet. A platform letter (EJM, JOE, Interfolio, AJO) is written once and reused, so the real workload is the number of distinct platforms plus the direct-email items.
A4: Referee | B4: Applications naming this referee | C4: Earliest letters due | D4: Due by 31 Oct | E4: Due 1–8 Nov | F4: Due 9–16 Nov | G4: Due 17–30 Nov | H4: Due Dec 2026 | I4: Due 2027 | J4: Via EJM / JOE (one upload) | K4: Via Interfolio / AJO | L4: Other (own portal, direct email, names only) | M4: Needs the referee to act separately
A5: Benigno | B5: =COUNTIF(Applications!$K$5:$K$145,"*Benigno*") -> 141 | C5: =IF(COUNTIFS(Applications!$O$5:$O$145,"*Benigno*",Applications!$F$5:$F$145,">="&TODAY())=0,"",_xlfn.MINIFS(Applications!$F$5:$F$145,Applications!$O$5:$O$145,"*Reis*",Applications!$F$5:$F$145,">="&TODAY())) -> 46325 | D5: =COUNTIFS(Applications!$O$5:$O$145,"*Benigno*",Applications!$F$5:$F$145,"<="&DATE(2026,10,31)) -> 2 | E5: =COUNTIFS(Applications!$O$5:$O$145,"*Benigno*",Applications!$F$5:$F$145,">="&DATE(2026,11,1),Applications!$F$5:$F$145,"<="&DATE(2026,11,8)) -> 14 | F5: =COUNTIFS(Applications!$O$5:$O$145,"*Benigno*",Applications!$F$5:$F$145,">="&DATE(2026,11,9),Applications!$F$5:$F$145,"<="&DATE(2026,11,16)) -> 56 | G5: =COUNTIFS(Applications!$O$5:$O$145,"*Benigno*",Applications!$F$5:$F$145,">="&DATE(2026,11,17),Applications!$F$5:$F$145,"<="&DATE(2026,11,30)) -> 37 | H5: =COUNTIFS(Applications!$O$5:$O$145,"*Benigno*",Applications!$F$5:$F$145,">="&DATE(2026,12,1),Applications!$F$5:$F$145,"<="&DATE(2026,12,31)) -> 17 | I5: =COUNTIFS(Applications!$O$5:$O$145,"*Benigno*",Applications!$F$5:$F$145,">="&DATE(2027,1,1)) -> 6 | J5: =COUNTIFS(Applications!$O$5:$O$145,"*Benigno*",Applications!$I$5:$I$145,"*EconJobMarket*")+COUNTIFS(Applications!$O$5:$O$145,"*Benigno*",Applications!$I$5:$I$145,"*JOE*") -> 85 | K5: =COUNTIFS(Applications!$O$5:$O$145,"*Benigno*",Applications!$I$5:$I$145,"*Interfolio*")+COUNTIFS(Applications!$O$5:$O$145,"*Benigno*",Applications!$I$5:$I$145,"*AcademicJobsOnline*") -> 24 | L5: =B5-J5-K5 -> 32 | M5: =COUNTIFS(Applications!$O$5:$O$145,"*Benigno*",Applications!$P$5:$P$145,"Referee action needed") -> 28
A6: Reis | B6: =COUNTIF(Applications!$O$5:$O$145,"*Reis*") -> 139 | C6: =IF(COUNTIFS(Applications!$O$5:$O$145,"*Reis*",Applications!$F$5:$F$145,">="&TODAY())=0,"",_xlfn.MINIFS(Applications!$F$5:$F$145,Applications!$O$5:$O$145,"*Reis*",Applications!$F$5:$F$145,">="&TODAY())) -> 46325 | D6: =COUNTIFS(Applications!$O$5:$O$145,"*Reis*",Applications!$F$5:$F$145,"<="&DATE(2026,10,31)) -> 2 | E6: =COUNTIFS(Applications!$O$5:$O$145,"*Reis*",Applications!$F$5:$F$145,">="&DATE(2026,11,1),Applications!$F$5:$F$145,"<="&DATE(2026,11,8)) -> 14 | F6: =COUNTIFS(Applications!$O$5:$O$145,"*Reis*",Applications!$F$5:$F$145,">="&DATE(2026,11,9),Applications!$F$5:$F$145,"<="&DATE(2026,11,16)) -> 56 | G6: =COUNTIFS(Applications!$O$5:$O$145,"*Reis*",Applications!$F$5:$F$145,">="&DATE(2026,11,17),Applications!$F$5:$F$145,"<="&DATE(2026,11,30)) -> 37 | H6: =COUNTIFS(Applications!$O$5:$O$145,"*Reis*",Applications!$F$5:$F$145,">="&DATE(2026,12,1),Applications!$F$5:$F$145,"<="&DATE(2026,12,31)) -> 15 | I6: =COUNTIFS(Applications!$O$5:$O$145,"*Reis*",Applications!$F$5:$F$145,">="&DATE(2027,1,1)) -> 6 | J6: =COUNTIFS(Applications!$O$5:$O$145,"*Reis*",Applications!$I$5:$I$145,"*EconJobMarket*")+COUNTIFS(Applications!$O$5:$O$145,"*Reis*",Applications!$I$5:$I$145,"*JOE*") -> 85 | K6: =COUNTIFS(Applications!$O$5:$O$145,"*Reis*",Applications!$I$5:$I$145,"*Interfolio*")+COUNTIFS(Applications!$O$5:$O$145,"*Reis*",Applications!$I$5:$I$145,"*AcademicJobsOnline*") -> 24 | L6: =B6-J6-K6 -> 30 | M6: =COUNTIFS(Applications!$O$5:$O$145,"*Reis*",Applications!$P$5:$P$145,"Referee action needed") -> 26
A7: Hofmann | B7: =COUNTIF(Applications!$O$5:$O$145,"*Hofmann*") -> 88 | C7: =IF(COUNTIFS(Applications!$O$5:$O$145,"*Hofmann*",Applications!$F$5:$F$145,">="&TODAY())=0,"",_xlfn.MINIFS(Applications!$F$5:$F$145,Applications!$O$5:$O$145,"*Hofmann*",Applications!$F$5:$F$145,">="&TODAY())) -> 46327 | D7: =COUNTIFS(Applications!$O$5:$O$145,"*Hofmann*",Applications!$F$5:$F$145,"<="&DATE(2026,10,31)) -> 0 | E7: =COUNTIFS(Applications!$O$5:$O$145,"*Hofmann*",Applications!$F$5:$F$145,">="&DATE(2026,11,1),Applications!$F$5:$F$145,"<="&DATE(2026,11,8)) -> 12 | F7: =COUNTIFS(Applications!$O$5:$O$145,"*Hofmann*",Applications!$F$5:$F$145,">="&DATE(2026,11,9),Applications!$F$5:$F$145,"<="&DATE(2026,11,16)) -> 39 | G7: =COUNTIFS(Applications!$O$5:$O$145,"*Hofmann*",Applications!$F$5:$F$145,">="&DATE(2026,11,17),Applications!$F$5:$F$145,"<="&DATE(2026,11,30)) -> 19 | H7: =COUNTIFS(Applications!$O$5:$O$145,"*Hofmann*",Applications!$F$5:$F$145,">="&DATE(2026,12,1),Applications!$F$5:$F$145,"<="&DATE(2026,12,31)) -> 12 | I7: =COUNTIFS(Applications!$O$5:$O$145,"*Hofmann*",Applications!$F$5:$F$145,">="&DATE(2027,1,1)) -> 4 | J7: =COUNTIFS(Applications!$O$5:$O$145,"*Hofmann*",Applications!$I$5:$I$145,"*EconJobMarket*")+COUNTIFS(Applications!$O$5:$O$145,"*Hofmann*",Applications!$I$5:$I$145,"*JOE*") -> 65 | K7: =COUNTIFS(Applications!$O$5:$O$145,"*Hofmann*",Applications!$I$5:$I$145,"*Interfolio*")+COUNTIFS(Applications!$O$5:$O$145,"*Hofmann*",Applications!$I$5:$I$145,"*AcademicJobsOnline*") -> 14 | L7: =B7-J7-K7 -> 9 | M7: =COUNTIFS(Applications!$O$5:$O$145,"*Hofmann*",Applications!$P$5:$P$145,"Referee action needed") -> 10
A8: Chaudhary | B8: =COUNTIF(Applications!$O$5:$O$145,"*Chaudhary*") -> 38 | C8: =IF(COUNTIFS(Applications!$O$5:$O$145,"*Chaudhary*",Applications!$F$5:$F$145,">="&TODAY())=0,"",_xlfn.MINIFS(Applications!$F$5:$F$145,Applications!$O$5:$O$145,"*Chaudhary*",Applications!$F$5:$F$145,">="&TODAY())) -> 46327 | D8: =COUNTIFS(Applications!$O$5:$O$145,"*Chaudhary*",Applications!$F$5:$F$145,"<="&DATE(2026,10,31)) -> 0 | E8: =COUNTIFS(Applications!$O$5:$O$145,"*Chaudhary*",Applications!$F$5:$F$145,">="&DATE(2026,11,1),Applications!$F$5:$F$145,"<="&DATE(2026,11,8)) -> 1 | F8: =COUNTIFS(Applications!$O$5:$O$145,"*Chaudhary*",Applications!$F$5:$F$145,">="&DATE(2026,11,9),Applications!$F$5:$F$145,"<="&DATE(2026,11,16)) -> 15 | G8: =COUNTIFS(Applications!$O$5:$O$145,"*Chaudhary*",Applications!$F$5:$F$145,">="&DATE(2026,11,17),Applications!$F$5:$F$145,"<="&DATE(2026,11,30)) -> 15 | H8: =COUNTIFS(Applications!$O$5:$O$145,"*Chaudhary*",Applications!$F$5:$F$145,">="&DATE(2026,12,1),Applications!$F$5:$F$145,"<="&DATE(2026,12,31)) -> 1 | I8: =COUNTIFS(Applications!$O$5:$O$145,"*Chaudhary*",Applications!$F$5:$F$145,">="&DATE(2027,1,1)) -> 2 | J8: =COUNTIFS(Applications!$O$5:$O$145,"*Chaudhary*",Applications!$I$5:$I$145,"*EconJobMarket*")+COUNTIFS(Applications!$O$5:$O$145,"*Chaudhary*",Applications!$I$5:$I$145,"*JOE*") -> 15 | K8: =COUNTIFS(Applications!$O$5:$O$145,"*Chaudhary*",Applications!$I$5:$I$145,"*Interfolio*")+COUNTIFS(Applications!$O$5:$O$145,"*Chaudhary*",Applications!$I$5:$I$145,"*AcademicJobsOnline*") -> 8 | L8: =B8-J8-K8 -> 15 | M8: =COUNTIFS(Applications!$O$5:$O$145,"*Chaudhary*",Applications!$P$5:$P$145,"Referee action needed") -> 11
